[2025-10-27 15:21:46] CSV job start for DSN019-S_MtLemmon 2025-03-31..2025-11-30
[2025-10-27 15:21:46] Running: python3 /Users/soazdsn/DSN/scripts/DSN_generate_csv.py --label DSN019-S_MtLemmon --from 2025-03-31 --to 2025-11-30 --site-repo /Users/soazdsn/DSN/soazcomms.github.io
python3: can't open file '/Users/soazdsn/DSN/scripts/DSN_generate_csv.py': [Errno 2] No such file or directory
[2025-10-27 15:30:16] CSV job start for DSN019-S_MtLemmon 2025-03-31..2025-11-30
[2025-10-27 15:30:17] Running: python3 /Users/soazdsn/DSN/DSNcode/DSN_generate_csv.py --label DSN019-S_MtLemmon --from 2025-03-31 --to 2025-11-30 --site-repo /Users/soazdsn/DSN/soazcomms.github.io
soazcomms@darksky.org
[main dd33dc3b] Publish CSV for DSN019-S_MtLemmon 20250331..20251130
 3 files changed, 7 insertions(+), 4 deletions(-)
To https://github.com/soazcomms/soazcomms.github.io
 ! [rejected]          main -> main (fetch first)
error: failed to push some refs to 'https://github.com/soazcomms/soazcomms.github.io'
hint: Updates were rejected because the remote contains work that you do
hint: not have locally. This is usually caused by another repository pushing
hint: to the same ref. You may want to first integrate the remote changes
hint: (e.g., 'git pull ...') before pushing again.
hint: See the 'Note about fast-forwards' in 'git push --help' for details.
Traceback (most recent call last):
  File "/Users/soazdsn/DSN/DSNcode/DSN_generate_csv.py", line 77, in <module>
    main()
  File "/Users/soazdsn/DSN/DSNcode/DSN_generate_csv.py", line 71, in main
    git_safe_commit(repo, f"Publish CSV for {label} {dfrom}..{dto}")
  File "/Users/soazdsn/DSN/DSNcode/DSN_generate_csv.py", line 25, in git_safe_commit
    run(["git","push"], cwd=repo_dir)
  File "/Users/soazdsn/DSN/DSNcode/DSN_generate_csv.py", line 13, in run
    subprocess.run(cmd, cwd=cwd, check=True)
  File "/Users/soazdsn/anaconda3/envs/python310/lib/python3.10/subprocess.py", line 526, in run
    raise CalledProcessError(retcode, process.args,
subprocess.CalledProcessError: Command '['git', 'push']' returned non-zero exit status 1.
